2018-04-15 21:18:22,012 ERROR: Exception on /index [GET] [in /home/bers/PycharmProjects/microblog/venv/lib/python3.6/site-packages/flask/app.py:1560]
Traceback (most recent call last):
  File "/home/bers/PycharmProjects/microblog/venv/lib/python3.6/site-packages/sqlalchemy/engine/base.py", line 1193, in _execute_context
    context)
  File "/home/bers/PycharmProjects/microblog/venv/lib/python3.6/site-packages/sqlalchemy/engine/default.py", line 507, in do_execute
    cursor.execute(statement, parameters)
sqlite3.OperationalError: no such table: followers

The above exception was the direct cause of the following exception:

Traceback (most recent call last):
  File "/home/bers/PycharmProjects/microblog/venv/lib/python3.6/site-packages/flask/app.py", line 1982, in wsgi_app
    response = self.full_dispatch_request()
  File "/home/bers/PycharmProjects/microblog/venv/lib/python3.6/site-packages/flask/app.py", line 1614, in full_dispatch_request
    rv = self.handle_user_exception(e)
  File "/home/bers/PycharmProjects/microblog/venv/lib/python3.6/site-packages/flask/app.py", line 1517, in handle_user_exception
    reraise(exc_type, exc_value, tb)
  File "/home/bers/PycharmProjects/microblog/venv/lib/python3.6/site-packages/flask/_compat.py", line 33, in reraise
    raise value
  File "/home/bers/PycharmProjects/microblog/venv/lib/python3.6/site-packages/flask/app.py", line 1612, in full_dispatch_request
    rv = self.dispatch_request()
  File "/home/bers/PycharmProjects/microblog/venv/lib/python3.6/site-packages/flask/app.py", line 1598, in dispatch_request
    return self.view_functions[rule.endpoint](**req.view_args)
  File "/home/bers/PycharmProjects/microblog/venv/lib/python3.6/site-packages/flask_login/utils.py", line 261, in decorated_view
    return func(*args, **kwargs)
  File "/home/bers/PycharmProjects/microblog/app/routes.py", line 29, in index
    posts = [
  File "/home/bers/PycharmProjects/microblog/venv/lib/python3.6/site-packages/sqlalchemy/orm/query.py", line 2726, in all
    return list(self)
  File "/home/bers/PycharmProjects/microblog/venv/lib/python3.6/site-packages/sqlalchemy/orm/query.py", line 2878, in __iter__
    return self._execute_and_instances(context)
  File "/home/bers/PycharmProjects/microblog/venv/lib/python3.6/site-packages/sqlalchemy/orm/query.py", line 2901, in _execute_and_instances
    result = conn.execute(querycontext.statement, self._params)
  File "/home/bers/PycharmProjects/microblog/venv/lib/python3.6/site-packages/sqlalchemy/engine/base.py", line 948, in execute
    return meth(self, multiparams, params)
  File "/home/bers/PycharmProjects/microblog/venv/lib/python3.6/site-packages/sqlalchemy/sql/elements.py", line 269, in _execute_on_connection
    return connection._execute_clauseelement(self, multiparams, params)
  File "/home/bers/PycharmProjects/microblog/venv/lib/python3.6/site-packages/sqlalchemy/engine/base.py", line 1060, in _execute_clauseelement
    compiled_sql, distilled_params
  File "/home/bers/PycharmProjects/microblog/venv/lib/python3.6/site-packages/sqlalchemy/engine/base.py", line 1200, in _execute_context
    context)
  File "/home/bers/PycharmProjects/microblog/venv/lib/python3.6/site-packages/sqlalchemy/engine/base.py", line 1413, in _handle_dbapi_exception
    exc_info
  File "/home/bers/PycharmProjects/microblog/venv/lib/python3.6/site-packages/sqlalchemy/util/compat.py", line 203, in raise_from_cause
    reraise(type(exception), exception, tb=exc_tb, cause=cause)
  File "/home/bers/PycharmProjects/microblog/venv/lib/python3.6/site-packages/sqlalchemy/util/compat.py", line 186, in reraise
    raise value.with_traceback(tb)
  File "/home/bers/PycharmProjects/microblog/venv/lib/python3.6/site-packages/sqlalchemy/engine/base.py", line 1193, in _execute_context
    context)
  File "/home/bers/PycharmProjects/microblog/venv/lib/python3.6/site-packages/sqlalchemy/engine/default.py", line 507, in do_execute
    cursor.execute(statement, parameters)
sqlalchemy.exc.OperationalError: (sqlite3.OperationalError) no such table: followers [SQL: 'SELECT anon_1.post_id AS anon_1_post_id, anon_1.post_body AS anon_1_post_body, anon_1.post_timestamp AS anon_1_post_timestamp, anon_1.post_user_id AS anon_1_post_user_id \nFROM (SELECT post.id AS post_id, post.body AS post_body, post.timestamp AS post_timestamp, post.user_id AS post_user_id \nFROM post JOIN followers ON followers.followed_id = post.user_id \nWHERE followers.follower_id = ? UNION SELECT post.id AS post_id, post.body AS post_body, post.timestamp AS post_timestamp, post.user_id AS post_user_id \nFROM post \nWHERE post.user_id = ?) AS anon_1 ORDER BY anon_1.post_timestamp DESC'] [parameters: (2, 2)] (Background on this error at: http://sqlalche.me/e/e3q8)
2018-04-15 21:18:25,700 INFO: Microblog startup [in /home/bers/PycharmProjects/microblog/app/__init__.py:45]
